/ext3/miniconda3/lib/python3.11/site-packages/torchvision/models/_utils.py:135: UserWarning: Using 'weights' as positional parameter(s) is deprecated since 0.13 and may be removed in the future. Please use keyword parameter(s) instead.
  warnings.warn(
Traceback (most recent call last):
  File "/ext3/miniconda3/lib/python3.11/site-packages/pandas/core/indexes/base.py", line 3790, in get_loc
    return self._engine.get_loc(casted_key)
           ^^^^^^^^^^^^^^^^^^^^^^^^^^^^^^^^
  File "index.pyx", line 152, in pandas._libs.index.IndexEngine.get_loc
  File "index.pyx", line 181, in pandas._libs.index.IndexEngine.get_loc
  File "pandas/_libs/hashtable_class_helper.pxi", line 7080, in pandas._libs.hashtable.PyObjectHashTable.get_item
  File "pandas/_libs/hashtable_class_helper.pxi", line 7088, in pandas._libs.hashtable.PyObjectHashTable.get_item
KeyError: 'new_sns_group_4'

The above exception was the direct cause of the following exception:

Traceback (most recent call last):
  File "/scratch/paa9751/mlhc-project/erm-training-true.py", line 379, in <module>
    train_dataloader, val_dataloader, test_dataloader = load_resized_data(chexpert_dir, mimic_dir, args.IMAGE_SIZE, args.NORMALISE, args.TRANSFORM, args.NWORKERS, args.BATCH_SIZE, args.BORDER_SZ, 'new_sns_group_4') 
                                                        ^^^^^^^^^^^^^^^^^^^^^^^^^^^^^^^^^^^^^^^^^^^^^^^^^^^^^^^^^^^^^^^^^^^^^^^^^^^^^^^^^^^^^^^^^^^^^^^^^^^^^^^^^^^^^^^^^^^^^^^^^^^^^^^^^^^^^^^^^^^^^^^^^^^^^^^^^^^^^^
  File "/scratch/paa9751/mlhc-project/dataloader.py", line 296, in load_resized_data
    mimic_train_dataset = MIMICDataset('new_path', mimic_df[mimic_df.split=='train'], IMAGE_SIZE, NORMALISE, TRANSFORM, BORDER_SZ, GROUP_CNAME,split_idx)
                          ^^^^^^^^^^^^^^^^^^^^^^^^^^^^^^^^^^^^^^^^^^^^^^^^^^^^^^^^^^^^^^^^^^^^^^^^^^^^^^^^^^^^^^^^^^^^^^^^^^^^^^^^^^^^^^^^^^^^^^^^^^^^^^^
  File "/scratch/paa9751/mlhc-project/dataloader.py", line 151, in __init__
    self.groups= dataframe[group_cname].tolist()
                 ~~~~~~~~~^^^^^^^^^^^^^
  File "/ext3/miniconda3/lib/python3.11/site-packages/pandas/core/frame.py", line 3896, in __getitem__
    indexer = self.columns.get_loc(key)
              ^^^^^^^^^^^^^^^^^^^^^^^^^
  File "/ext3/miniconda3/lib/python3.11/site-packages/pandas/core/indexes/base.py", line 3797, in get_loc
    raise KeyError(key) from err
KeyError: 'new_sns_group_4'
